2018-09-25 11:28:06,216 :: root :: ERROR :: Upload of ET_07-2011 has failed.
Traceback (most recent call last):
  File "/Users/daviddralle/Dropbox/research/bess_v2/github/data/gee_asset_manager/gee_asset_manager/batch_uploader.py", line 115, in upload
    task_id = __start_ingestion_task(asset_request)
  File "/Users/daviddralle/anaconda2/envs/py3k/lib/python3.5/site-packages/retrying.py", line 49, in wrapped_f
    return Retrying(*dargs, **dkw).call(f, *args, **kw)
  File "/Users/daviddralle/anaconda2/envs/py3k/lib/python3.5/site-packages/retrying.py", line 206, in call
    return attempt.get(self._wrap_exception)
  File "/Users/daviddralle/anaconda2/envs/py3k/lib/python3.5/site-packages/retrying.py", line 247, in get
    six.reraise(self.value[0], self.value[1], self.value[2])
  File "/Users/daviddralle/anaconda2/envs/py3k/lib/python3.5/site-packages/six.py", line 693, in reraise
    raise value
  File "/Users/daviddralle/anaconda2/envs/py3k/lib/python3.5/site-packages/retrying.py", line 200, in call
    attempt = Attempt(fn(*args, **kwargs), attempt_number, False)
  File "/Users/daviddralle/Dropbox/research/bess_v2/github/data/gee_asset_manager/gee_asset_manager/batch_uploader.py", line 175, in __start_ingestion_task
    task_id = ee.data.newTaskId(1)[0]
  File "/Users/daviddralle/anaconda2/envs/py3k/lib/python3.5/site-packages/ee/data.py", line 587, in newTaskId
    return send_('/newtaskid', args)
  File "/Users/daviddralle/anaconda2/envs/py3k/lib/python3.5/site-packages/ee/data.py", line 889, in send_
    response, content = send_with_backoff()
  File "/Users/daviddralle/anaconda2/envs/py3k/lib/python3.5/site-packages/ee/data.py", line 880, in send_with_backoff
    url, method=opt_method, body=payload, headers=headers)
  File "/Users/daviddralle/anaconda2/envs/py3k/lib/python3.5/site-packages/oauth2client/transport.py", line 175, in new_request
    redirections, connection_type)
  File "/Users/daviddralle/anaconda2/envs/py3k/lib/python3.5/site-packages/oauth2client/transport.py", line 282, in request
    connection_type=connection_type)
  File "/Users/daviddralle/anaconda2/envs/py3k/lib/python3.5/site-packages/httplib2/__init__.py", line 1514, in request
    (response, content) = self._request(conn, authority, uri, request_uri, method, body, headers, redirections, cachekey)
  File "/Users/daviddralle/anaconda2/envs/py3k/lib/python3.5/site-packages/httplib2/__init__.py", line 1264, in _request
    (response, content) = self._conn_request(conn, request_uri, method, body, headers)
  File "/Users/daviddralle/anaconda2/envs/py3k/lib/python3.5/site-packages/httplib2/__init__.py", line 1217, in _conn_request
    response = conn.getresponse()
  File "/Users/daviddralle/anaconda2/envs/py3k/lib/python3.5/http/client.py", line 1198, in getresponse
    response.begin()
  File "/Users/daviddralle/anaconda2/envs/py3k/lib/python3.5/http/client.py", line 297, in begin
    version, status, reason = self._read_status()
  File "/Users/daviddralle/anaconda2/envs/py3k/lib/python3.5/http/client.py", line 258, in _read_status
    line = str(self.fp.readline(_MAXLINE + 1), "iso-8859-1")
  File "/Users/daviddralle/anaconda2/envs/py3k/lib/python3.5/socket.py", line 576, in readinto
    return self._sock.recv_into(b)
  File "/Users/daviddralle/anaconda2/envs/py3k/lib/python3.5/ssl.py", line 937, in recv_into
    return self.read(nbytes, buffer)
  File "/Users/daviddralle/anaconda2/envs/py3k/lib/python3.5/ssl.py", line 799, in read
    return self._sslobj.read(len, buffer)
  File "/Users/daviddralle/anaconda2/envs/py3k/lib/python3.5/ssl.py", line 583, in read
    v = self._sslobj.read(len, buffer)
TimeoutError: [Errno 60] Operation timed out
